Workbook

Sheet Top200_ig_20260126
A1: Temperature_order | B1: person_name | C1: ig_name | D1: ig_id | E1: done | F1: ig_url | G1: ig_private | H1: ig_notSure_notFound | I1: ig_repeat | J1: temperature_link
A2: 1 | B2: 館長 陳之漢 | C2: 陳之漢 | D2: power3067830678 | E2: 1 | F2: https://www.instagram.com/power3067830678/ | J2: https://dailyview.tw/top100/item/1247?theme=36&range=30
A3: 2 | B3: 蔡阿嘎 蔡緯嘉 | C3: 蔡阿嘎 | D3: yga0721 | E3: 1 | F3: https://www.instagram.com/yga0721/ | J3: https://dailyview.tw/top100/item/1246?theme=36&range=30
A4: 3 | B4: 嘎嫂二伯&蔡波能 | C4: 嘎嫂二伯 | D4: 2uncle987 | E4: g | F4: https://www.instagram.com/2uncle987/ | J4: https://dailyview.tw/top100/item/19379?theme=36&range=30
A5: 4 | B5: 蔡桃貴 | C5: 蔡桃貴 | D5: tsaigray2018 | E5: 1 | F5: https://www.instagram.com/tsaigray2018/ | J5: https://dailyview.tw/top100/item/14457?theme=36&range=30
A6: 5 | B6: Cheap 鄭才暐 | C6: 鄭才暐 | D6: cheapaoe | E6: 1 | F6: https://www.instagram.com/cheapaoe/ | J6: https://dailyview.tw/top100/item/15683?theme=36&range=30
A7: 6 | B7: 張志祺（志祺七七 X 圖文不符） | C7: 志祺 | D7: shasha77.daily | E7: 1 | F7: https://www.instagram.com/shasha77.daily/ | J7: https://dailyview.tw/top100/item/12004?theme=36&range=30
A8: 7 | B8: 亞拉（貓貓蟲咖波） | C8: Bugcat Capoo | D8: bugcat_capoo | E8: 1 | F8: https://www.instagram.com/bugcat_capoo/ | J8: https://dailyview.tw/top100/item/3047?theme=36&range=30
A9: 8 | B9: 歷史哥 李易修 | C9: 歷史哥李易修 | D9: mrhisbro | E9: 1 | F9: https://www.instagram.com/mrhisbro/ | J9: https://dailyview.tw/top100/item/21386?theme=36&range=30
A10: 9 | B10: 鍾明軒 | C10: 鍾明軒 | D10: big_star_ken | E10: 999 | F10: https://www.instagram.com/big_star_ken/ | J10: https://dailyview.tw/top100/item/1257?theme=36&range=30
A11: 10 | B11: 晚安小雞 | C11: smallville780 | D11: smallville780 | E11: 998 | F11: https://www.instagram.com/smallville780/ | G11: 1 | J11: https://dailyview.tw/top100/item/23512?theme=36&range=30
A12: 11 | B12: 寒國人 張紹群 | C12: 張紹群 | D12: a22731391 | E12: 1 | F12: https://www.instagram.com/a22731391/ | J12: https://dailyview.tw/top100/item/27722?theme=36&range=30
A13: 12 | B13: 唐綺陽 | C13: 唐綺陽Jesse Tang | D13: jessetang11 | E13: 1 | F13: https://www.instagram.com/jessetang11/ | J13: https://dailyview.tw/top100/item/1271?theme=36&range=30
A14: 13 | B14: 反骨男孩 WACKYBOYS | C14: 反骨WACKYBOYS | D14: wackyboys520 | E14: 1 | F14: https://www.instagram.com/wackyboys520/ | J14: https://dailyview.tw/top100/item/7805?theme=36&range=30
A15: 14 | B15: 丁特 Dinter | C15: 丁特頻道 | D15: dinteroffical | E15: 1 | F15: https://www.instagram.com/dinteroffical/ | J15: https://dailyview.tw/top100/item/2798?theme=36&range=30
A16: 15 | B16: 八炯 温子渝（攝徒日記Fun TV） | C16: 八炯 | D16: musiclin_1107 | E16: 1 | F16: https://www.instagram.com/musiclin_1107/ | J16: https://dailyview.tw/top100/item/27721?theme=36&range=30
A17: 16 | B17: 有感筆電 Daptoper | C17: 有感筆電Daptoper | D17: daptoper | E17: 1 | F17: https://www.instagram.com/daptoper/ | J17: https://dailyview.tw/top100/item/18056?theme=36&range=30
A18: 17 | B18: 恩恩老師EanTV | C18: 恩恩老師EanTV | D18: happyeantv | E18: 1 | F18: https://www.instagram.com/happyeantv/ | J18: https://dailyview.tw/top100/item/19335?theme=36&range=30
A19: 18 | B19: Den | C19: DenQ | D19: denqdenq | E19: 1 | F19: https://www.instagram.com/denqdenq/ | J19: https://dailyview.tw/top100/item/14754?theme=36&range=30
A20: 19 | B20: 居妮 Ginny | C20: GINNY HSIEH | D20: ning3035 | F20: https://www.instagram.com/ning3035/ | J20: https://dailyview.tw/top100/item/13079?theme=36&range=30
A21: 20 | B21: 黃明志 | C21: 黃明志 | D21: namewee | E21: 1 | F21: https://www.instagram.com/namewee/ | J21: https://dailyview.tw/top100/item/3677?theme=36&range=30
A22: 21 | B22: Andy老師 王崇睿 | C22: Andy老師 | D22: andy1994x | E22: 1 | F22: https://www.instagram.com/andy1994x/ | J22: https://dailyview.tw/top100/item/26853?theme=36&range=30
A23: 22 | B23: 呂捷 | C23: 呂捷 | D23: vgsa.tw | E23: 1 | F23: https://www.instagram.com/vgsa.tw/ | J23: https://dailyview.tw/top100/item/12235?theme=36&range=30
A24: 23 | B24: 雨揚（雨揚樂活家族） | C24: 招財｜數字測驗 | D24: yu.young_fate | E24: 1 | F24: https://www.instagram.com/yu.young_fate/ | J24: https://dailyview.tw/top100/item/18047?theme=36&range=30
A25: 24 | B25: 叉雞 | C25: 叉雞Chah G🤍 | D25: chah.ggggg | E25: 999 | F25: https://www.instagram.com/chah.ggggg/ | J25: https://dailyview.tw/top100/item/28879?theme=36&range=30
A26: 25 | B26: 薔薔 林嘉凌 | C26: 薔薔林嘉凌Lin chia ling | D26: chialing_maze | F26: https://www.instagram.com/chialing_maze/ | J26: https://dailyview.tw/top100/item/2495?theme=36&range=30
A27: 25 | B27: 薔薔 林嘉凌 | C27: 薔栗膠 | D27: linchialing_maze | E27: 1 | F27: https://www.instagram.com/linchialing_maze/ | J27: https://dailyview.tw/top100/item/2495?theme=36&range=30
A28: 26 | B28: 呱吉 邱威傑 | C28: 呱吉 | D28: froggychiu | F28: https://www.instagram.com/froggychiu/ | J28: https://dailyview.tw/top100/item/7651?theme=36&range=30
A29: 27 | B29: 葳老闆 周品均 | C29: 周品均 | D29: mayukichou | F29: https://www.instagram.com/mayukichou/ | J29: https://dailyview.tw/top100/item/22461?theme=36&range=30
A30: 28 | B30: Inokawa Hajime井川一 | C30: 井川一InokawaHajime | D30: yaobinyang | E30: 1 | F30: https://www.instagram.com/yaobinyang/ | J30: https://dailyview.tw/top100/item/20924?theme=36&range=30
A31: 29 | B31: 老王 王倚隆 | C31: 跟著老王好好學股票 | D31: oldwangstock | E31: 1 | F31: https://www.instagram.com/oldwangstock/ | J31: https://dailyview.tw/top100/item/19376?theme=36&range=30
A32: 30 | B32: 黃氏兄弟 | C32: 黃氏兄弟 | D32: huangbrotherss | E32: 1 | F32: https://www.instagram.com/huangbrotherss/ | J32: https://dailyview.tw/top100/item/10692?theme=36&range=30
A33: 31 | B33: 阿滴 都省瑞 | C33: 阿滴 | D33: rayduenglish | F33: https://www.instagram.com/rayduenglish/ | J33: https://dailyview.tw/top100/item/1274?theme=36&range=30
A34: 32 | B34: 張家寧（秘月期POPOO） | C34: 秘月期POPOO | D34: popoo_5200 | E34: 1 | F34: https://www.instagram.com/popoo_5200/ | J34: https://dailyview.tw/top100/item/27090?theme=36&range=30
A35: 33 | B35: 蹦闆 呂育銓 | C35: 蹦闆呂育銓 | D35: 1988.bomb | E35: 1 | F35: https://www.instagram.com/1988.bomb/ | J35: https://dailyview.tw/top100/item/23778?theme=36&range=30
A36: 34 | B36: 亞洲統神 張嘉航 | C36: 張嘉航 | D36: godtoneasia | E36: 1 | F36: https://www.instagram.com/godtoneasia/ | J36: https://dailyview.tw/top100/item/1255?theme=36&range=30
A37: 35 | B37: 許伯&簡芝（倉鼠人） | C37: 許伯&簡芝 | D37: hsu_po_ | E37: 1 | F37: https://www.instagram.com/hsu_po_/ | J37: https://dailyview.tw/top100/item/18045?theme=36&range=30
A38: 36 | B38: 琳妲 林羿禎 | C38: 琳妲-林羿禎💕 | D38: linda831212 | F38: https://www.instagram.com/linda831212/ | J38: https://dailyview.tw/top100/item/22984?theme=36&range=30
A39: 37 | B39: 曾博恩 | C39: 曾博恩Brian Tseng | D39: brianptseng | F39: https://www.instagram.com/brianptseng/ | J39: https://dailyview.tw/top100/item/11950?theme=36&range=30
A40: 38 | B40: 儒哥 | C40: Ru儒哥 | D40: ruge1222 | E40: 1 | F40: https://www.instagram.com/ruge1222/ | J40: https://dailyview.tw/top100/item/18076?theme=36&range=30
...

Sheet aisa100
A1: Aisa_Order | B1: person_name | C1: ig_name | D1: ig_id | E1: ig_strong_id | F1: done | H1: posts | I1: Followers | J1: Following | K1: ig_url | L1: ig_url ig_private | M1: ig_notSure_notFound | N1: ig_repeat | O1: category | P1: followers
A2: 1 | B2: 蔡阿嘎 | C2: 蔡阿嘎 | D2: yga0721 | E2: 45717781 | F2: 1 | G2: {=_xludf.XLOOKUP(D2,aisa200!D:D,aisa200!F:F,"")} -> #NAME? | H2: 8178 | I2: 1495461 | J2: 501 | K2: https://www.instagram.com/yga0721/ | O2: 趣味搞笑 | P2: 5893557
A3: 2 | B3: PanSci-泛科學 | C3: PanSci 泛科學 | D3: pansci | E3: 1455058965 | F3: 1 | G3: {=_xludf.XLOOKUP(D3,aisa200!D:D,aisa200!F:F,"")} -> #NAME? | H3: 1453 | I3: 283652 | J3: 399 | K3: https://www.instagram.com/pansci/ | O3: 知識教育 | P3: 1830902
A4: 3 | B4: 黃阿瑪的後宮生活 | C4: 黃阿瑪的後宮生活 | D4: fumeancat | E4: 1399123752 | F4: 1 | G4: {=_xludf.XLOOKUP(D4,aisa200!D:D,aisa200!F:F,"")} -> #NAME? | H4: 4550 | I4: 1050878 | J4: 159 | K4: https://www.instagram.com/fumeancat/ | O4: 寵物 | P4: 4117370
A5: 4 | B5: 小象愛出門 | C5: 小象愛出門 | D5: elephant_gogo | E5: 484667815 | F5: g | G5: {=_xludf.XLOOKUP(D5,aisa200!D:D,aisa200!F:F,"")} -> #NAME? | H5: 1888 | I5: 183273 | J5: 1129 | K5: https://www.instagram.com/elephant_gogo/ | O5: 美食料理,旅遊 | P5: 1158083
A6: 5 | B6: 那對夫妻 | C6: 那對夫妻Nico&Kim | D6: 1006nk | E6: 1701651749 | F6: 1 | G6: {=_xludf.XLOOKUP(D6,aisa200!D:D,aisa200!F:F,"")} -> #NAME? | H6: 3146 | I6: 1030978 | J6: 3 | K6: https://www.instagram.com/1006nk/ | O6: 趣味搞笑,家庭母嬰,表演藝術 | P6: 4576655
A7: 6 | B7: 大蛇丸 | C7: 大蛇丸 | D7: jam_cutepig | E7: 2214964723 | F7: 1 | G7: {=_xludf.XLOOKUP(D7,aisa200!D:D,aisa200!F:F,"")} -> #NAME? | H7: 882 | I7: 551530 | J7: 390 | K7: https://www.instagram.com/jam_cutepig/ | O7: 趣味搞笑 | P7: 2042767
A8: 7 | B8: Aries艾瑞絲 | C8: Aries艾瑞絲 | D8: aries_8248 | E8: 453456033 | F8: g | G8: {=_xludf.XLOOKUP(D8,aisa200!D:D,aisa200!F:F,"")} -> #NAME? | H8: 2044 | I8: 779766 | J8: 943 | K8: https://www.instagram.com/aries_8248/ | O8: 美食料理,表演藝術,趣味搞笑 | P8: 4774089
A9: 8 | B9: 陳彥婷 | C9: 陳彥婷 Tiffany | D9: thetiffanychen | E9: 4053642540 | F9: 1 | G9: {=_xludf.XLOOKUP(D9,aisa200!D:D,aisa200!F:F,"")} -> #NAME? | H9: 2147 | I9: 642973 | J9: 352 | K9: https://www.instagram.com/thetiffanychen/ | O9: 趣味搞笑 | P9: 1585007
A10: 9 | B10: Joeman | C10: Joeman 九妹 | D10: joemanweng | E10: 360484090 | F10: g | G10: {=_xludf.XLOOKUP(D10,aisa200!D:D,aisa200!F:F,"")} -> #NAME? | H10: 1615 | I10: 666819 | J10: 996 | K10: https://www.instagram.com/joemanweng/ | O10: 美食料理,3C科技,趣味搞笑 | P10: 3981236
A11: 10 | B11: 一隻阿圓 | C11: 一隻阿圓 | D11: nanaciaociao | E11: 313471712 | F11: 1 | G11: {=_xludf.XLOOKUP(D11,aisa200!D:D,aisa200!F:F,"")} -> #NAME? | H11: 3373 | I11: 563686 | J11: 593 | K11: https://www.instagram.com/nanaciaociao/ | O11: 美妝保養,時尚潮流,旅遊 | P11: 1725846
A12: 11 | B12: 豆漿--Soybean-Milk | C12: 豆漿-SoybeanMilk | D12: soybeanmilk_cat | E12: 5556187464 | F12: 1 | G12: {=_xludf.XLOOKUP(D12,aisa200!D:D,aisa200!F:F,"")} -> #NAME? | H12: 2242 | I12: 433921 | J12: 34 | K12: https://www.instagram.com/soybeanmilk_cat/ | O12: 寵物 | P12: 1834682
A13: 12 | B13: 貓貓蟲-咖波 | C13: Bugcat Capoo | D13: bugcat_capoo | E13: 2122019014 | F13: 1 | G13: {=_xludf.XLOOKUP(D13,aisa200!D:D,aisa200!F:F,"")} -> #NAME? | H13: 1735 | I13: 2136350 | J13: 291 | K13: https://www.instagram.com/bugcat_capoo/ | O13: 表演藝術 | P13: 6526761
A14: 13 | B14: 人類超有病-Baxuan | C14: 霸軒BAXUAN | D14: baxuan_ig | E14: 1959578996 | F14: g | G14: {=_xludf.XLOOKUP(D14,aisa200!D:D,aisa200!F:F,"")} -> #NAME? | H14: 1066 | I14: 742233 | J14: 2830 | K14: https://www.instagram.com/baxuan_ig/ | O14: 表演藝術,趣味搞笑 | P14: 2784459
A15: 14 | B15: 蕾菈-Lyla | C15: 蕾菈 Lyla | D15: la.112814 | E15: 534488377 | F15: g | G15: {=_xludf.XLOOKUP(D15,aisa200!D:D,aisa200!F:F,"")} -> #NAME? | H15: 1486 | I15: 1147024 | J15: 1627 | K15: https://www.instagram.com/la.112814/ | O15: 趣味搞笑 | P15: 2924293
A16: 15 | B16: 好味小姐 | C16: 好味小姐與蛋捲,短褲,麻糊,米香,橘皮,本丸,圓仔,More | D16: ladyflavor | E16: 3417748590 | F16: 1 | G16: {=_xludf.XLOOKUP(D16,aisa200!D:D,aisa200!F:F,"")} -> #NAME? | H16: 2094 | I16: 395768 | J16: 112 | K16: https://www.instagram.com/ladyflavor/ | O16: 美食料理,寵物 | P16: 1591823
A17: 15 | B17: 好味小姐 | C17: 好味小姐脆脆 | D17: ladyflavor_cui | E17: 3656815405 | F17: 1 | G17: {=_xludf.XLOOKUP(D17,aisa200!D:D,aisa200!F:F,"")} -> #NAME? | H17: 1378 | I17: 369611 | J17: 122 | K17: https://www.instagram.com/ladyflavor_cui/ | O17: 美食料理,寵物 | P17: 1591823
A18: 15 | B18: 好味小姐 | C18: 好味小姐腦波弱跟Podcast | D18: ladyflavor_nowpo | E18: 53675526308 | F18: 1 | G18: {=_xludf.XLOOKUP(D18,aisa200!D:D,aisa200!F:F,"")} -> #NAME? | H18: 472 | I18: 205735 | J18: 9 | K18: https://www.instagram.com/ladyflavor_nowpo/ | O18: 美食料理,寵物 | P18: 1591823
A19: 16 | B19: 小A辣 | C19: 小A辣🌶️ | D19: ala780705 | E19: 5703523434 | F19: g | G19: {=_xludf.XLOOKUP(D19,aisa200!D:D,aisa200!F:F,"")} -> #NAME? | H19: 1744 | I19: 354298 | J19: 1499 | K19: https://www.instagram.com/ala780705/ | O19: 趣味搞笑 | P19: 2844787
A20: 17 | B20: 泱泱-LYNN | C20: 泱泱LYNN | D20: lynnwu0219_2 | E20: 47642521277 | F20: 1 | G20: {=_xludf.XLOOKUP(D20,aisa200!D:D,aisa200!F:F,"")} -> #NAME? | H20: 21 | I20: 76276 | J20: 93 | K20: https://www.instagram.com/lynnwu0219_2/ | O20: 帶貨分潤 | P20: 1966599
A21: 18 | B21: 千千進食中 | C21: 千千 | D21: khshu_ | E21: 254432523 | F21: g | G21: {=_xludf.XLOOKUP(D21,aisa200!D:D,aisa200!F:F,"")} -> #NAME? | H21: 1002 | I21: 891802 | J21: 974 | K21: https://www.instagram.com/khshu_/ | O21: 美食料理 | P21: 3603862
A22: 19 | B22: Sandy-珊迪 | C22: Sandykaka 珊迪 | D22: sandykaka_ | E22: 2620202 | F22: 1 | G22: {=_xludf.XLOOKUP(D22,aisa200!D:D,aisa200!F:F,"")} -> #NAME? | H22: 3279 | I22: 292906 | J22: 479 | K22: https://www.instagram.com/sandykaka_/ | O22: 美食料理,寵物,遊戲電玩 | P22: 892734
A23: 20 | B23: 飆悍 | C23: 陳之漢 | D23: power3067830678 | E23: 3791242285 | F23: 1 | G23: {=_xludf.XLOOKUP(D23,aisa200!D:D,aisa200!F:F,"")} -> #NAME? | H23: 1841 | I23: 782079 | J23: 150 | K23: https://www.instagram.com/power3067830678/ | O23: 運動健身,遊戲電玩,時事討論 | P23: 3377635
A24: 21 | B24: Yun-Chou | C24: Yun Chou | D24: riceandshine.co | E24: 851583 | F24: g | G24: {=_xludf.XLOOKUP(D24,aisa200!D:D,aisa200!F:F,"")} -> #NAME? | H24: 2961 | I24: 834659 | J24: 993 | K24: https://www.instagram.com/riceandshine.co/ | O24: 家庭母嬰 | P24: 1591069
A25: 22 | B25: 琳妲-林羿禎 | C25: 琳妲-林羿禎💕 | D25: linda831212 | E25: 262292089 | F25: g | G25: {=_xludf.XLOOKUP(D25,aisa200!D:D,aisa200!F:F,"")} -> #NAME? | H25: 5232 | I25: 1036871 | J25: 2416 | K25: https://www.instagram.com/linda831212/ | O25: 表演藝術,趣味搞笑 | P25: 2676124
A26: 23 | B26: How-Fun-如何爽 | C26: HowHow | D26: howhowhasfriends | E26: 6505088311 | F26: 1 | G26: {=_xludf.XLOOKUP(D26,aisa200!D:D,aisa200!F:F,"")} -> #NAME? | H26: 1921 | I26: 523443 | J26: 103 | K26: https://www.instagram.com/howhowhasfriends | O26: 趣味搞笑 | P26: 2759513
A27: 24 | B27: 魔術Channel---Davio | C27: 🎩Davio🎩 | D27: davio_magic | E27: 3025123501 | F27: g | G27: {=_xludf.XLOOKUP(D27,aisa200!D:D,aisa200!F:F,"")} -> #NAME? | H27: 2093 | I27: 351680 | J27: 682 | K27: https://www.instagram.com/davio_magic/ | O27: 表演藝術 | P27: 1018319
A28: 25 | B28: HOOK | C28: HOOK | D28: helloiamhook | E28: 6666970922 | F28: 1 | G28: {=_xludf.XLOOKUP(D28,aisa200!D:D,aisa200!F:F,"")} -> #NAME? | H28: 1154 | I28: 648553 | J28: 448 | K28: https://www.instagram.com/helloiamhook/ | O28: 寵物,旅遊,美食料理 | P28: 2870332
A29: 26 | B29: lan&Eric | C29: The DoDo Men - 嘟嘟人 | D29: thedodomen | E29: 22597217534 | F29: 1 | G29: {=_xludf.XLOOKUP(D29,aisa200!D:D,aisa200!F:F,"")} -> #NAME? | H29: 1101 | I29: 609185 | J29: 482 | K29: https://www.instagram.com/thedodomen/ | O29: 旅遊,趣味搞笑 | P29: 2209418
A30: 27 | B30: 嘎嫂二伯 | C30: 嘎嫂二伯 | D30: 2uncle987 | E30: 2113732341 | F30: g | G30: {=_xludf.XLOOKUP(D30,aisa200!D:D,aisa200!F:F,"")} -> #NAME? | H30: 4245 | I30: 774220 | J30: 703 | K30: https://www.instagram.com/2uncle987/ | O30: 旅遊,家庭母嬰 | P30: 1197000
A31: 28 | B31: Peter-Su | C31: Peter Su | D31: peter825 | E31: 2059966 | F31: g | G31: {=_xludf.XLOOKUP(D31,aisa200!D:D,aisa200!F:F,"")} -> #NAME? | H31: 3594 | I31: 668099 | J31: 930 | K31: https://www.instagram.com/peter825/ | O31: 旅遊,知識教育 | P31: 1439199
A32: 29 | B32: Sandy-&-Mandy | C32: Sandy&Mandy | D32: sandymandy_official | E32: 5694299090 | F32: 1 | G32: {=_xludf.XLOOKUP(D32,aisa200!D:D,aisa200!F:F,"")} -> #NAME? | H32: 586 | I32: 519307 | J32: 248 | K32: https://www.instagram.com/sandymandy_official/ | O32: 表演藝術 | P32: 4341726
A33: 30 | B33: 愛莉莎莎-Alisasa | C33: 愛莉莎莎Alisasa 🐨 | D33: goodalicia | E33: 328949039 | F33: g | G33: {=_xludf.XLOOKUP(D33,aisa200!D:D,aisa200!F:F,"")} -> #NAME? | H33: 1637 | I33: 615843 | J33: 1279 | K33: https://www.instagram.com/goodalicia/ | O33: 美妝保養,時尚潮流 | P33: 2280213
A34: 31 | B34: 彼得爸與蘇珊媽 | C34: 彼得爸與蘇珊媽 | D34: peter_and_susan | E34: 22917989 | F34: g | G34: {=_xludf.XLOOKUP(D34,aisa200!D:D,aisa200!F:F,"")} -> #NAME? | H34: 3181 | I34: 115573 | J34: 1267 | K34: https://www.instagram.com/peter_and_susan/ | O34: 旅遊,家庭母嬰,帶貨分潤 | P34: 740997
A35: 32 | B35: 江老師 | C35: 我是江老師 | D35: teacherchiang | E35: 30136496472 | F35: g | G35: {=_xludf.XLOOKUP(D35,aisa200!D:D,aisa200!F:F,"")} -> #NAME? | H35: 1922 | I35: 308786 | J35: 624 | K35: https://www.instagram.com/teacherchiang | O35: 表演藝術,時尚潮流,家庭母嬰 | P35: 1325283
A36: 33 | B36: 元元 | C36: 元 元 | D36: 1105ya | E36: 506333587 | F36: 1 | G36: {=_xludf.XLOOKUP(D36,aisa200!D:D,aisa200!F:F,"")} -> #NAME? | H36: 1524 | I36: 1106945 | J36: 560 | K36: https://www.instagram.com/1105ya/ | O36: 時尚潮流 | P36: 2063109
A37: 34 | B37: 林進-飛醺卑鄙-fashion-baby | C37: 林進Lingin 林東進飛醺卑鄙Fashionbaby | D37: lingin1209 | E37: 371630480 | F37: g | G37: {=_xludf.XLOOKUP(D37,aisa200!D:D,aisa200!F:F,"")} -> #NAME? | H37: 8194 | I37: 722044 | J37: 2244 | K37: https://www.instagram.com/lingin1209/ | O37: 趣味搞笑 | P37: 2525842
A38: 35 | B38: 我是老爸-我不要當爸! | C38: 我是老爸，我不要當爸 | D38: daddy.iam | E38: 3638274950 | F38: g | G38: {=_xludf.XLOOKUP(D38,aisa200!D:D,aisa200!F:F,"")} -> #NAME? | H38: 554 | I38: 102766 | J38: 301 | K38: https://www.instagram.com/daddy.iam/ | O38: 旅遊,美食料理 | P38: 1212086
A39: 36 | B39: 小葵-XiaoKui | C39: 小葵 XiaoKui | D39: miao11255 | E39: 1673522323 | F39: g | G39: {=_xludf.XLOOKUP(D39,aisa200!D:D,aisa200!F:F,"")} -> #NAME? | H39: 1374 | I39: 178445 | J39: 764 | K39: https://www.instagram.com/miao11255/ | O39: 遊戲電玩 | P39: 732923
A40: 37 | B40: 星期天 | C40: 星期天 Sunday | D40: sundayright_dub | E40: 1795150072 | F40: g | G40: {=_xludf.XLOOKUP(D40,aisa200!D:D,aisa200!F:F,"")} -> #NAME? | H40: 1950 | I40: 180562 | J40: 1612 | K40: https://www.instagram.com/sundayright_dub/ | O40: 綜合其他 | P40: 1267313
...

Sheet aisa200
A1: Aisa_Order | B1: person_name | C1: ig_name | D1: ig_id | E1: ig_strong_id | F1: posts | G1: Followers | H1: Following | I1: ig_url | J1: category
A2: 1 | B2: 蔡阿嘎 | C2: 蔡阿嘎 | D2: yga0721 | E2: 45717781 | F2: 8178 | G2: 1495461 | H2: 501 | I2: https://www.instagram.com/yga0721/ | J2: 趣味搞笑
A3: 2 | B3: Joeman | C3: Joeman 九妹 | D3: joemanweng | E3: 360484090 | F3: 1615 | G3: 666819 | H3: 996 | I3: https://www.instagram.com/joemanweng/ | J3: 美食料理,3C科技,趣味搞笑
A4: 3 | B4: 黃阿瑪的後宮生活 | C4: 黃阿瑪的後宮生活 | D4: fumeancat | E4: 1399123752 | F4: 4550 | G4: 1050878 | H4: 159 | I4: https://www.instagram.com/fumeancat/ | J4: 寵物
A5: 4 | B5: 千千進食中 | C5: 千千 | D5: khshu_ | E5: 254432523 | F5: 1002 | G5: 891802 | H5: 974 | I5: https://www.instagram.com/khshu_/ | J5: 美食料理
A6: 5 | B6: 小象愛出門 | C6: 小象愛出門 | D6: elephant_gogo | E6: 484667815 | F6: 1888 | G6: 183273 | H6: 1129 | I6: https://www.instagram.com/elephant_gogo/ | J6: 美食料理,旅遊
A7: 6 | B7: 那對夫妻 | C7: 那對夫妻Nico&Kim | D7: 1006nk | E7: 1701651749 | F7: 3146 | G7: 1030978 | H7: 3 | I7: https://www.instagram.com/1006nk/ | J7: 趣味搞笑,家庭母嬰,表演藝術
A8: 7 | B8: How-Fun-如何爽 | C8: HowHow | D8: howhowhasfriends | E8: 6505088311 | F8: 1921 | G8: 523443 | H8: 103 | I8: https://www.instagram.com/howhowhasfriends | J8: 趣味搞笑
A9: 8 | B9: PanSci-泛科學 | C9: PanSci 泛科學 | D9: pansci | E9: 1455058965 | F9: 1453 | G9: 283652 | H9: 399 | I9: https://www.instagram.com/pansci/ | J9: 知識教育
A10: 9 | B10: 一隻阿圓 | C10: 一隻阿圓 | D10: nanaciaociao | E10: 313471712 | F10: 3373 | G10: 563686 | H10: 593 | I10: https://www.instagram.com/nanaciaociao/ | J10: 美妝保養,時尚潮流,旅遊
A11: 10 | B11: 欸你這週要幹嘛 | C11: 欸你這週要幹嘛 | D11: arielsvlog_816 | E11: 8320554996 | F11: 1411 | G11: 708449 | H11: 473 | I11: https://www.instagram.com/arielsvlog_816/ | J11: 趣味搞笑
A12: 11 | B12: 77老大 | C12: 77老大 | D12: basil_77777 | E12: 5393203387 | F12: 1054 | G12: 395721 | H12: 591 | I12: https://www.instagram.com/zamy_ding/ | J12: 醫療健康,知識教育
A13: 12 | B13: 那個女生-Kiki | C13: 那個女生Kiki | D13: minikiki_0529 | E13: 6204281058 | F13: 1099 | G13: 289658 | H13: 511 | I13: https://www.instagram.com/minikiki_0529/ | J13: 美食料理,知識教育
... A15: 14 | B15: 好味小姐 | C15: 好味小姐與蛋捲,短褲,麻糊,米香,橘皮,本丸,圓仔,More | D15: ladyflavor | E15: 3417748590 | F15: 2094 | G15: 395768 | H15: 112 | I15: https://www.instagram.com/ladyflavor/ | J15: 美食料理,寵物
A16: 14 | B16: 好味小姐 | C16: 好味小姐脆脆 | D16: ladyflavor_cui | E16: 3656815405 | F16: 1378 | G16: 369611 | H16: 122 | I16: https://www.instagram.com/ladyflavor_cui/
A17: 14 | B17: 好味小姐 | C17: 好味小姐腦波弱跟Podcast | D17: ladyflavor_nowpo | E17: 53675526308 | F17: 472 | G17: 205735 | H17: 9 | I17: https://www.instagram.com/ladyflavor_nowpo/
A18: 15 | B18: 廉傑克曼 | C18: 張廉傑 RJ / 阿傑 | D18: jaychang0127 | E18: 328078093 | F18: 1855 | G18: 415002 | H18: 4032 | I18: https://www.instagram.com/jaychang0127/ | J18: 遊戲電玩
A19: 16 | B19: 江老師 | C19: 我是江老師 | D19: teacherchiang | E19: 30136496472 | F19: 1922 | G19: 308786 | H19: 624 | I19: https://www.instagram.com/teacherchiang | J19: 表演藝術,時尚潮流,家庭母嬰
A20: 17 | B20: 那些電影教我的事 | C20: 那些電影教我的事 | D20: lessonsfrommovies | E20: 485234984 | F20: 6816 | G20: 1484140 | H20: 87 | I20: https://www.instagram.com/lessonsfrommovies/ | J20: 影視評論
A21: 18 | B21: 豆漿--Soybean-Milk | C21: 豆漿-SoybeanMilk | D21: soybeanmilk_cat | E21: 5556187464 | F21: 2242 | G21: 433921 | H21: 34 | I21: https://www.instagram.com/soybeanmilk_cat/ | J21: 寵物
A22: 19 | B22: Onion-man-洋蔥先生與阿文 | C22: 洋蔥先生與阿文 | D22: onionman__ | E22: 1981431196 | F22: 1177 | G22: 458424 | H22: 925 | I22: https://www.instagram.com/onionman__/ | J22: 表演藝術,趣味搞笑
A23: 20 | B23: 人類超有病-Baxuan | C23: 霸軒BAXUAN | D23: baxuan_ig | E23: 1959578996 | F23: 1066 | G23: 742233 | H23: 2830 | I23: https://www.instagram.com/baxuan_ig/ | J23: 表演藝術,趣味搞笑
A24: 21 | B24: 大蛇丸 | C24: 大蛇丸 | D24: jam_cutepig | E24: 2214964723 | F24: 882 | G24: 551530 | H24: 390 | I24: https://www.instagram.com/jam_cutepig/ | J24: 趣味搞笑
A25: 22 | B25: Andy老師 | C25: Andy老師 | D25: andy1994x | E25: 4017891221 | F25: 391 | G25: 1241259 | H25: 57 | I25: https://www.instagram.com/andy1994x/ | J25: 趣味搞笑,表演藝術
A26: 23 | B26: 超認真少年-I'm-Serious | C26: 超認真少年 | D26: imseriou | E26: 8743462644 | F26: 1529 | G26: 138411 | H26: 751 | I26: https://www.instagram.com/imseriou/ | J26: 知識教育
A27: 24 | B27: 三原慧悟-Sanyuan_JAPAN | C27: 三原 慧悟/サンエン/Mr.3 | D27: sanyuan_japan | E27: 2036845994 | F27: 1147 | G27: 229384 | H27: 595 | I27: https://www.instagram.com/sanyuan_japan/ | J27: 旅遊,趣味搞笑
A28: 25 | B28: 貓貓蟲-咖波 | C28: Bugcat Capoo | D28: bugcat_capoo | E28: 2122019014 | F28: 1735 | G28: 2136350 | H28: 291 | I28: https://www.instagram.com/bugcat_capoo/ | J28: 表演藝術
A29: 26 | B29: Ian&Eric | C29: The DoDo Men - 嘟嘟人 | D29: thedodomen | E29: 22597217534 | F29: 1101 | G29: 609185 | H29: 482 | I29: https://www.instagram.com/thedodomen/ | J29: 旅遊,趣味搞笑
A30: 27 | B30: 黃氏兄弟 | C30: 黃氏兄弟 | D30: huangbrotherss | E30: 6231869789 | F30: 476 | G30: 454084 | H30: 2 | I30: https://www.instagram.com/huangbrotherss/ | J30: 趣味搞笑,表演藝術
A31: 28 | B31: 我得了一種吃菜就會死的病-微疼 | C31: 微疼 | D31: weiteng0710 | E31: 1325089238 | F31: 1429 | G31: 322374 | H31: 1071 | I31: ="https://www.instagram.com/"& D31&"/" -> https://www.instagram.com/weiteng0710/ | J31: 表演藝術,趣味搞笑
A32: 29 | B32: 琳妲-林羿禎 | C32: 琳妲-林羿禎💕 | D32: linda831212 | E32: 262292089 | F32: 5232 | G32: 1036871 | H32: 2416 | I32: https://www.instagram.com/linda831212/ | J32: 表演藝術,趣味搞笑
A33: 30 | B33: 白癡公主 | C33: 白癡公主 | D33: 87acup | E33: 323227199 | F33: 1801 | G33: 1002519 | H33: 515 | I33: https://www.instagram.com/87acup/ | J33: 趣味搞笑
A34: 31 | B34: KEOKI-BLACK布萊克薛薛 | C34: 布萊克薛薛Drangadrang | D34: k3okii | E34: 192726292 | F34: 1396 | G34: 232109 | H34: 389 | I34: https://www.instagram.com/k3okii/ | J34: 旅遊,美食料理
A35: 32 | B35: 厭世甜點店 | C35: 厭世甜點店 | D35: energydessert2019 | E35: 11941118848 | F35: 1266 | G35: 145675 | H35: 494 | I35: ="https://www.instagram.com/"& D35&"/" -> https://www.instagram.com/energydessert2019/ | J35: 美食料理
A36: 33 | B36: 陳彥婷 | C36: 陳彥婷 Tiffany | D36: thetiffanychen | E36: 4053642540 | F36: 2147 | G36: 642973 | H36: 352 | I36: https://www.instagram.com/thetiffanychen/ | J36: 趣味搞笑
A37: 34 | B37: 魚乾 | C37: 魚乾 | D37: annie72127 | E37: 310596431 | F37: 1809 | G37: 350257 | H37: 500 | I37: https://www.instagram.com/annie72127/ | J37: 寵物,遊戲電玩,趣味搞笑
A38: 35 | B38: 志祺七七 | C38: 志祺 | D38: shasha77.daily | E38: 7011513421 | F38: 1093 | G38: 238862 | H38: 552 | I38: https://www.instagram.com/shasha77.daily/ | J38: 知識教育,時事討論,高階經理人
A39: 36 | B39: HOOK | C39: HOOK | D39: helloiamhook | E39: 6666970922 | F39: 1154 | G39: 648553 | H39: 448 | I39: https://www.instagram.com/helloiamhook/ | J39: 寵物,旅遊,美食料理
A40: 37 | B40: 木曜4超玩 | C40: 木曜4超玩 | D40: muyao4 | E40: 5422332449 | F40: 817 | G40: 342007 | H40: 71 | I40: https://www.instagram.com/muyao4/ | J40: 旅遊
A41: 38 | B41: 丹妮婊姐 | C41: 丹妮婊姐星球 | D41: dannybeeech | E41: 1387337609 | F41: 1232 | G41: 257954 | H41: 2 | I41: https://www.instagram.com/dannybeeech/ | J41: 美妝保養,時尚潮流,趣味搞笑
...

Sheet aisa500
A1: 編號 | B1: 網紅名稱 | C1: 領域 | D1: 總粉絲數 | E1: 總影響力 | F1: 總互動參與 | G1: 總內容關聯
A2: 1 | B2: 蔡阿嘎 | C2: 趣味搞笑 | D2: 5893570 | E2: 5 | F2: 5 | G2: 4.3
A3: 2 | B3: Joeman | C3: 美食料理,3C科技,趣味搞笑 | D3: 3987069 | E3: 4.9 | F3: 4.9 | G3: 4.5
A4: 3 | B4: 黃阿瑪的後宮生活 | C4: 寵物 | D4: 4118794 | E4: 5 | F4: 5 | G4: 4
A5: 4 | B5: 千千進食中 | C5: 美食料理 | D5: 3609387 | E5: 5 | F5: 5 | G5: 3.6
A6: 5 | B6: 小象愛出門 | C6: 美食料理,旅遊 | D6: 1160238 | E6: 4.6 | F6: 4.7 | G6: 4.2
A7: 6 | B7: 那對夫妻 | C7: 趣味搞笑,家庭母嬰,表演藝術 | D7: 4578282 | E7: 5 | F7: 4.1 | G7: 4.1
A8: 7 | B8: How Fun 如何爽 | C8: 趣味搞笑 | D8: 2758663 | E8: 5 | F8: 4.5 | G8: 3.5
A9: 8 | B9: PanSci 泛科學 | C9: 知識教育 | D9: 1900400 | E9: 4.9 | F9: 4.8 | G9: 3.5
A10: 9 | B10: 一隻阿圓 | C10: 美妝保養,時尚潮流,旅遊 | D10: 1734796 | E10: 4.5 | F10: 4.1 | G10: 4.7
A11: 10 | B11: 欸你這週要幹嘛 | C11: 趣味搞笑 | D11: 2339911 | E11: 4.9 | F11: 4.7 | G11: 3.2
A12: 11 | B12: 77老大 | C12: 醫療健康,知識教育 | D12: 2808129 | E12: 5 | F12: 4.7 | G12: 3
A13: 12 | B13: 那個女生 Kiki | C13: 美食料理,知識教育 | D13: 1793484 | E13: 4.7 | F13: 4.2 | G13: 4.1
... A501: 500 | B501: 布萊登 Brandon | C501: 趣味搞笑 | D501: 371583 | E501: 2 | F501: 3.2 | G501: 1.2

Sheet 影片檢核
B1: list_name_from_realFinal | C1: csv_name | D1: data_dir_exist | E1: lost_file | F1: meta_tool_num | I1: 個別檔案檢核
A2: 157 | B2: 0_shufen | C2: 0_shufen_20260302151127.csv | D2: FALSE | E2: 0 | F2: -1
A3: 184 | B3: 1_shiuan_0 | C3: 1_shiuan_0_20260302151127.csv | D3: TRUE | E3: 0 | F3: 62
A4: 15 | B4: 1006nk | C4: 1006nk_20260302151127.csv | D4: FALSE | E4: 0 | F4: -1
A5: 88 | B5: 1105ya | C5: 1105ya_20260302151127.csv | D5: FALSE | E5: 0 | F5: -1
A6: 97 | B6: 20141010hero | C6: 20141010hero_20260302151127.csv | D6: TRUE | E6: 0 | F6: 14
A7: 110 | B7: 2uncle987 | C7: 2uncle987_20260302151127.csv | D7: FALSE | E7: 0 | F7: -1
A8: 194 | B8: 3ctim | C8: 3ctim_20260302151127.csv | D8: FALSE | E8: 0 | F8: -1
A9: 149 | B9: 5inana | C9: 5inana_20260302151127.csv | D9: FALSE | E9: 0 | F9: -1
A10: 99 | B10: 602avenue | C10: 602avenue_20260302151127.csv | D10: FALSE | E10: 0 | F10: -1
A11: 156 | B11: 6tan | C11: 6tan_20260302151127.csv | D11: FALSE | E11: 0 | F11: -1
A12: 132 | B12: 87acup | C12: 87acup_20260302151127.csv | D12: FALSE | E12: 0 | F12: -1
A13: 46 | B13: achusan0817 | C13: achusan0817_20260302151127.csv | D13: FALSE | E13: 0 | F13: -1
... A198: 196 | B198: zxsdexz | C198: zxsdexz_20260302151127.csv | D198: TRUE | E198: 20 | F198: 179

Sheet 工作表18
A1: Unnamed: 0 | B1: creation_time | C1: modified_time | D1: post_owner.name | E1: post_owner.username | F1: url | G1: id | H1: media_id | I1: 下載
A2: 0 | B2: 2024-12-31 19:43:32+00:00 | C2: 2025-01-01 06:33:38+00:00 | D2: 小A辣🌶️ | E2: ala780705 | F2: https://lookaside.facebook.com/mcl/multimedia/lookaside/?download_info=AZvvFyMhgpm44S_UwFmD2no5ue-GWlPrI6cnwnmEUfppHUbHrodloX4TJC41CO4xqPlzmz9rYzpUYUSPYasQZyNpftzr85wiwvFo-ZG36ejDSi9AK6k_dfMWxQEAjxKryy2hewOoDd_KRr7A4Y4Q9V3mgLOi | G2: 1.26e+15 | H2: 1.26e+15 | I2: deny for user | J2: 手動下載
A3: 7 | B3: 2025-01-14 20:02:56+00:00 | C3: 2025-01-15 01:43:05+00:00 | D3: 小A辣🌶️ | E3: ala780705 | F3: https://lookaside.facebook.com/mcl/multimedia/lookaside/?download_info=AZvjikK6iheceqqEserXBkNE1yH6OvqdQPKYCpkJOGUZpITNBvcKj8KULeSwcf6OfcpTH0rUqBCwLe9_lDTwwXVvwjxAjy4t5Tn7ndiLPCmWy96_hZu3258M6XtMOD-fq6NWwe_9KuT73PfJWzPdGTAst6d5 | G3: 1.43e+15 | H3: 1.43e+15 | I3: c
A4: 22 | B4: 2025-02-02 00:01:35+00:00 | C4: 2025-04-27 01:24:20+00:00 | D4: 小A辣🌶️ | E4: ala780705 | F4: https://lookaside.facebook.com/mcl/multimedia/lookaside/?download_info=AZu7jdDn_Yx4jHnOmzvZWzwAL-3wQpnx1JPl61s-HMCKsb7swydbcWNYD8ImDnKvQ-ZQ-9kjEmhrYTjca4-A_zi3YpeNzGMbC_pYM512HZBqwoIOBYGRgVIu9P4kdGXlD_ieHWZb8RXreaISnt7r-rOQef5y | G4: 1.63e+15 | H4: 1.63e+15 | I4: c
A5: 23 | B5: 2025-02-02 00:05:27+00:00 | C5: 2025-08-28 18:40:50+00:00 | D5: 小A辣🌶️ | E5: ala780705 | F5: https://lookaside.facebook.com/mcl/multimedia/lookaside/?download_info=AZuWLXgpwdYNO3t803mboQQyaZVJaQoWxYn1nAmecdjpBjCCpXrxgubcpXVNNLY6599ujQpGeJara1f2_nq8eUC_gCv_CYhmrtWt8PIMVPmi-_xFyatJY44Dd3I9wbC2D0pFybxPe4v-81pNRmaNi7ZjJgA | G5: 879000000000000 | H5: 879000000000000 | I5: c
A6: 44 | B6: 2025-03-10 13:20:01+00:00 | C6: 2025-09-14 11:33:48+00:00 | D6: 小A辣🌶️ | E6: ala780705 | F6: https://lookaside.facebook.com/mcl/multimedia/lookaside/?download_info=AZs3hdXZY7yuZ0VeQp7AXiEOxd-h-AZ_JBjrsVKSA7O389brS7N9g2uGJf54ODpWKiFaYhyUeS4e7qTbqKDh8w9qnwHDANOVz5cc7xVf7TAH2ysw5y7S6BcFs6y2BaJHJQ2yWT9PFJmxLoR2H7GQCMR0CW8Ztg | G6: 2.55e+16 | H6: 2.55e+16 | I6: c
A7: 45 | B7: 2025-03-10 13:23:07+00:00 | C7: 2025-09-20 17:42:36+00:00 | D7: 小A辣🌶️ | E7: ala780705 | F7: https://lookaside.facebook.com/mcl/multimedia/lookaside/?download_info=AZsNBCEDy4Jmf1T238rDAxAQJn7WJLe4V8YQMV63GItDiSeqrsLogB6SS7QH_zkiyrwVbIgz4tIo-liAL0jiZC5QaLtElG1ygI5yMjwNrYFwvbFkxiw40Dfpqgg83kKf9cZIpjfBEaFXxjytvJstALhALMg | G7: 847000000000000 | H7: 847000000000000 | I7: c
A8: 86 | B8: 2025-06-17 12:53:51+00:00 | C8: 2025-09-08 04:54:29+00:00 | D8: 小A辣🌶️ | E8: ala780705 | F8: https://lookaside.facebook.com/mcl/multimedia/lookaside/?download_info=AZsXcgE1v-N2mMvajTzkFo_Y_QUy2SLki-2pCOgI6cSE9jfy6fh1Dx1XbYxcPqks3DrIqrxsTJDjwHbH8sjVNs-LGGnobcg4eCuhw7-TCz0Q_PlrN_DSr_AdnLnNI2coif5mtO8MIZRlYR_bXjiLJnR9haK1 | G8: 2.03e+15 | H8: 2.03e+15 | I8: c
A9: 118 | B9: 2025-10-14 14:01:16+00:00 | C9: 2025-10-17 16:11:21+00:00 | D9: 小A辣🌶️ | E9: ala780705 | F9: https://lookaside.facebook.com/mcl/multimedia/lookaside/?download_info=AZuq1IaGOzL2fgcg_ns1fwY7s7uCrg8qs9iiqHCUtzMfZ4DnCIWTe8TgwEoKZ_vp-TkkKAq1xWY7IijAh6LfTnFtZ63PLDZj1ZChQj0VzKPJwLqafSLWVRF-zz8eSt6zO_F5MlWU27vKrhvlKBRrYbqNYuwM | G9: 4.15e+15 | H9: 4.15e+15 | I9: c
A10: 0 | B10: 2025-03-08 11:08:29+00:00 | C10: 2025-03-08 12:28:33+00:00 | D10: 艾爾文 | E10: alvin701 | F10: https://lookaside.facebook.com/mcl/multimedia/lookaside/?download_info=AZsqGpx6wpvbC_JGu1VoPwhPthp7PIt2AMOcEfuwRXmZNiVald6p-z82B8xzTnaCvigDnP-gYbroq2sZvtR5KpsbNjnruKASUG0c7fdaThWNto-XJI29PDz5d64Fj5V9qoBOPuWAMY2ODLG94WMWDFC3tCQ | G10: 880000000000000 | H10: 880000000000000 | I10: Media Access Expired | J10: ig真的沒有
A11: 8 | B11: 2025-04-11 10:00:00+00:00 | C11: 2025-04-12 09:40:08+00:00 | D11: 黃大謙 | E11: da_chien_huang | F11: https://lookaside.facebook.com/mcl/multimedia/lookaside/?download_info=AZu6jCN5X9j95_sgl2EfOaW3Bk4yvWlvRsng1nSyeRkF_rx7G3OSelPIimllkxmC_3wzPvWVgwNcCY_0L0msV6n4kf1ClRlv4ZQQHnnhx3rgZ1f3tK8SjG6SDQ6zoaaMBh_-EQTE9LmKLh-c7a2NsakE992h | G11: 1.62e+15 | H11: 1.62e+15 | I11: c
A12: 9 | B12: 2025-04-20 04:00:00+00:00 | C12: 2025-09-12 06:12:49+00:00 | D12: 黃大謙 | E12: da_chien_huang | F12: https://lookaside.facebook.com/mcl/multimedia/lookaside/?download_info=AZu6WzQzZ-qgRhavZ2ajkDG8QCYFwmtQa1IgvFHs4F9A1J4hxIkBahzIQ7H2Y_BR8C0qqq1QX45f3YgFQht4NvPhE2OBhKC7OvFK4YD-5Othlx-_r80U7HJlTWcdGiNqKaKDfYxemnLL698WUiVRyeN_SK8x | G12: 1.89e+15 | H12: 1.89e+15 | I12: c
A13: 10 | B13: 2025-04-25 10:00:00+00:00 | C13: 2025-07-29 09:56:13+00:00 | D13: 黃大謙 | E13: da_chien_huang | F13: https://lookaside.facebook.com/mcl/multimedia/lookaside/?download_info=AZvBTx4281-_CsLnauotRbSfIh-WQlTXbXep74qd4RmvYk6nE40D6JxaI8RqpWgLL4FwzR-SbZD1J--NWi2PGwdAgVvH6EuCjr1wzoPx_8i1bvBtt9wkh1vcxWICC1yA9Ylk56B5pm4adGkrLlwX7Ba9rzA | G13: 793000000000000 | H13: 793000000000000 | I13: c
A14: 11 | B14: 2025-05-06 10:09:24+00:00 | C14: 2025-07-25 12:31:04+00:00 | D14: 黃大謙 | E14: da_chien_huang | F14: https://lookaside.facebook.com/mcl/multimedia/lookaside/?download_info=AZskyDn5OsIWDjSZZyDMmJMqc94dfTsTDyIaNX471qKTEnaE7MbwINFXjvHBgdGi18ERYMTIC8k9eYeJWoUGdRE4odrlPNwN8PddeNJhQGCRvwAyt1d7hzgA0kZSmpnM8VYuF0HVFey-SXl6Thb_3OUle5VR | G14: 1.93e+15 | H14: 1.93e+15 | I14: c
A15: 12 | B15: 2025-05-15 09:55:50+00:00 | C15: 2025-09-25 13:31:32+00:00 | D15: 黃大謙 | E15: da_chien_huang | F15: https://lookaside.facebook.com/mcl/multimedia/lookaside/?download_info=AZvPAfEpHTHzyx4FcTFLZkJ1AqzHa2fW_KdPAi6myTX85OpX5YkZ_RqBYjFmN_PqacCJyXGjLHBFJvUj4VD8wTGY2NQ0PdAAIP7qRhwxU3fUlV7B9BCUhM3r-cZMQNHlGBEbkHj6moN4Kz82QLY6bL_Fn3Kz | G15: 2.31e+15 | H15: 2.31e+15 | I15: c
A16: 13 | B16: 2025-05-19 04:00:00+00:00 | C16: 2025-12-15 03:46:23+00:00 | D16: 黃大謙 | E16: da_chien_huang | F16: https://lookaside.facebook.com/mcl/multimedia/lookaside/?download_info=AZtWxmn7OOdvk3SFSB-At31D-LlCYpk1FAv7TBNyS2MEHhcEG8xGJjdD3vNOjcAasiABLQB1H440F3qBIxUS_OOdURRSOPOZKJyoopnOryuvs1rVjs9w60Vje6_1zLm9p0hLUJHr0nzzVZeY9xxer93GPHt1 | G16: 1.92e+15 | H16: 1.92e+15 | I16: c
A17: 15 | B17: 2025-04-16 10:48:54+00:00 | C17: 2025-04-30 02:00:54+00:00 | D17: 我是老爸，我不要當爸 | E17: daddy.iam | F17: https://lookaside.facebook.com/mcl/multimedia/lookaside/?download_info=AZtapzSYIhVWvlsNqf9zySD7SE6f4x9mWr-G5O51ZnXLxSUrNF7oBmJng7xaQYr7Fi_IuFMA_wF2CI1dfIGfHQgzueJiZ1_rUdMbUL6Fp10oeu4EzNhrJXCGBxa_ojz5YCI4Xm6f7RJdj57MEw3IGoBBX0U_ | G17: 1.42e+15 | H17: 1.42e+15 | I17: c
A18: 16 | B18: 2025-04-28 10:28:05+00:00 | C18: 2025-04-29 14:28:09+00:00 | D18: 我是老爸，我不要當爸 | E18: daddy.iam | F18: https://lookaside.facebook.com/mcl/multimedia/lookaside/?download_info=AZs0zeSGVi291azMLgsHcCH1f-sBomBLkIYjDUHVrxojJjk5bw9SVKMqk3aS4fjhErhX8qDU65lPoQgsiZagn0ijVbkM2p3Lx8itFa4TDC--ODM-pASaOq_IJHJ-ROHemFCzgZRDfUGtee1a24cw9V0Lzfmd | G18: 1.33e+15 | H18: 1.33e+15 | I18: c
A19: 17 | B19: 2025-04-30 12:47:45+00:00 | C19: 2025-04-30 15:47:54+00:00 | D19: 我是老爸，我不要當爸 | E19: daddy.iam | F19: https://lookaside.facebook.com/mcl/multimedia/lookaside/?download_info=AZtTcfNk482QeQMy-h7zFpBA1JKo__1rRy5mKbGMvSKNQ_Dn7EU1S0oCMp6fYiAvYbJL50DNfSgbuNQadMvzLvAbXx14tDCTClyqFXgkCeG3b1qyU1NNe9hrB_Mu3S2r2vyaSs9PD921kWAmF7-VZzp6ZsUq | G19: 1.25e+15 | H19: 1.25e+15 | I19: c
A20: 18 | B20: 2025-05-01 15:06:06+00:00 | C20: 2025-05-02 11:56:11+00:00 | D20: 我是老爸，我不要當爸 | E20: daddy.iam | F20: https://lookaside.facebook.com/mcl/multimedia/lookaside/?download_info=AZvJuHRXOEOubWLS0h4seq5BfnB89nnpBWc7nIthMkwxAK1xY5ZLR9yk2P9_JtHi-iFil0ytRocs-QdUmpiFnnEDfarq9K4IWnJ1x314y4XYwliSFz_SXp_yq4fE4cKB_ERM_nl7a6YYucgSquK0OcctPWvw | G20: 1.93e+15 | H20: 1.93e+15 | I20: c
A21: 19 | B21: 2025-05-02 11:38:30+00:00 | C21: 2025-05-02 12:48:34+00:00 | D21: 我是老爸，我不要當爸 | E21: daddy.iam | F21: https://lookaside.facebook.com/mcl/multimedia/lookaside/?download_info=AZvliF9_9h1oxT8qBbPuiej_gVgCYX-YqtCvhFV6xX9msZ8mYIHXoRrlhrlnVxPAFxHShb1O51cTYzimVCpkusb_KNQe8fG28t86fOIZJqS1OQHw5gtaGAYOQCT8pKhUYxuI8gi9MFIdV86ZZBQkG8HPCmEX | G21: 1.19e+15 | H21: 1.19e+15 | I21: c
A22: 20 | B22: 2025-05-05 14:11:53+00:00 | C22: 2025-05-05 23:41:58+00:00 | D22: 我是老爸，我不要當爸 | E22: daddy.iam | F22: https://lookaside.facebook.com/mcl/multimedia/lookaside/?download_info=AZtTqMifWD3J2UjbFA1jDqzkIvIYAOpEXqQQ_B9sAtssAMJDkVGT_toAIzGhIb9-mwSQZ6jTPh6TEUmqAowZVhetbVNIbQ1NYE1FxMoIhsbOzRXRqU7fKeRTH3txmIU3gE6oAAcG8gt8CC-bqRGzUlbeQA4 | G22: 910000000000000 | H22: 910000000000000 | I22: c
... A72: 67 | B72: 2025-12-18 13:47:53+00:00 | C72: 2025-12-20 14:47:57+00:00 | D72: YING 林岱縈 | E72: daiying0 | F72: https://lookaside.facebook.com/mcl/multimedia/lookaside/?download_info=AZuyGu42dcQrGJG2kEOUoRh6S_EMHVRHJt0bm0Qhu8CxMQJFqCjpsFN6LD8D4OatrNjbRAXNCY-ix797_oDexI49wRX5052gUxM6OpwXu_hyUrmGN8P4I_iYpLam7NmS3vLdrf0bJKKUbeEUesirgjCCSutn | G72: 1.19e+15 | H72: 1.19e+15 | I72: g
A73: 41 | B73: 2025-02-05 07:23:18+00:00 | C73: 2025-05-29 16:39:54+00:00 | D73: 🎩Davio🎩 | E73: davio_magic | F73: https://lookaside.facebook.com/mcl/multimedia/lookaside/?download_info=AZtfYWeix6g5YW3bIMXZq-FNS7CNsbzXDWeqPvEwSrGi0cg76MqkSV8LVkIaTQyRaK9tXlODZ6vqY63Ohw6p_CHN7znt49gFARgv2z_ZEnwmr8hDQOIHSvsdXu082lfr4Cjfg-fG3XcO3bdAXpR-ZjJQv1E | G73: 931000000000000 | H73: 931000000000000 | I73: Media Access Expired | J73: 已重新下載
A74: 92 | B74: 2025-03-20 06:38:13+00:00 | C74: 2025-09-12 06:23:34+00:00 | D74: 🎩Davio🎩 | E74: davio_magic | F74: https://lookaside.facebook.com/mcl/multimedia/lookaside/?download_info=AZvvjqweJtJSekxslO_NVgSezoXoFGFtTeXMl3cF4XfxQUbxvuHo0Xr7Spb7zs84emK_NXGkw-ACRgskTvQxtCQytap1hH-wihSKefuMhlBWRbQwIxS1ZtD3trRT-3_xpwtqLiiZCsV58ObWF26WBvBWADIt | G74: 2.04e+15 | H74: 2.04e+15 | I74: Media Access Expired | J74: 已重新下載
A75: 94 | B75: 2025-03-20 08:43:23+00:00 | C75: 2025-08-30 18:40:30+00:00 | D75: 🎩Davio🎩 | E75: davio_magic | F75: https://lookaside.facebook.com/mcl/multimedia/lookaside/?download_info=AZs41eGyQZeV6H4_v4zsiBTujXYrFd2wd_BfZ_UJBjbG2HIlV09u0SQVBhbr0F4tFGP_AwKfYtVsfoSySMLb1i8LAX1o6vnVEuMXjkskWGzoF-0wR0AJWhI4AMq1uMJEjqXRLpzahKG-iUWakGC0SIxpwzQ | G75: 880000000000000 | H75: 880000000000000 | I75: Media Access Expired | J75: 已重新下載
A76: 96 | B76: 2025-03-21 03:53:49+00:00 | C76: 2025-03-23 06:43:54+00:00 | D76: 🎩Davio🎩 | E76: davio_magic | F76: https://lookaside.facebook.com/mcl/multimedia/lookaside/?download_info=AZuJtQLyZ9dAzAp81EgQXZ_hXechE3NtrwvB_sO4auN-w8M3hfxMADzo8rEaq9EPZN22s-sd_0aN4HF0T2ksvSRmYOY2dsItQqz1CtsPGbXEoWanZxVCqRxG6gCCjWaDHJCBnYHdzIuNMt97ITO7SdWf_gff | G76: 1.54e+15 | H76: 1.54e+15 | I76: Media Access Expired | J76: 已重新下載
A77: 102 | B77: 2025-03-26 09:28:10+00:00 | C77: 2025-09-08 11:21:49+00:00 | D77: 🎩Davio🎩 | E77: davio_magic | F77: https://lookaside.facebook.com/mcl/multimedia/lookaside/?download_info=AZv17VwAqyObic5gZZ69liCvX9-LEGImF16CxyG-Qhz1hDI9aAtYhYJjkJb4cavT1VMeTUdziY0DJdBJACilzZrMhHNO2fN3ECpWPpJ1eGXve2l-qTnjX2JEtamGOUHP6TH6Dq4y0IvMCLXsLBLDX0K5M0M | G77: 865000000000000 | H77: 865000000000000 | I77: Media Access Expired | J77: 已重新下載
A78: 111 | B78: 2025-04-08 09:40:29+00:00 | C78: 2025-04-11 14:30:34+00:00 | D78: 🎩Davio🎩 | E78: davio_magic | F78: https://lookaside.facebook.com/mcl/multimedia/lookaside/?download_info=AZvnwEmZfhnwK3-jsAPFl8bUgiNb5UcxpPKUnFWa8bRmS2h5W6J9uRYqVoibSiqgmCvJRvNLjTo5FJ_h6Ivnv5i3Cu7DaSji_vGT6oPdpAa_VhtdiGO2TcxV7BgKk1TXLsrphmVvzMRVJdqirZVJPUQyCaGY | G78: 1.4e+15 | H78: 1.4e+15 | I78: Media Access Expired | J78: 已重新下載
A79: 115 | B79: 2025-04-12 18:21:17+00:00 | C79: 2025-09-05 12:01:47+00:00 | D79: 🎩Davio🎩 | E79: davio_magic | F79: https://lookaside.facebook.com/mcl/multimedia/lookaside/?download_info=AZt_KVgrF1qQscRPyBVD9TODU_ryzJslZpPhuf0l_0uYUQra34bkyeYGgv-Gwd3AB0y3rpGlOkIB2ir7vZY68VzvZIzmR8biUfC5s9fuJgYaxcV_KKi97d3OhP-drggiiO5taVx7lWlCNkBEmfAGO7WtAeE | G79: 786000000000000 | H79: 786000000000000 | I79: Media Access Expired | J79: 已重新下載
A80: 122 | B80: 2025-04-26 14:24:02+00:00 | C80: 2025-04-28 15:04:07+00:00 | D80: 🎩Davio🎩 | E80: davio_magic | F80: https://lookaside.facebook.com/mcl/multimedia/lookaside/?download_info=AZttEx7YaTnFjMyOuEDOwRLhTJAhcM_N0VOtGbf1MTrUPN1-_GR4GfBUrlwwILEvS6qvyMH5ctRXJb9h9RSNbUDxJYleeUCL50QMpeHTH-prTAUgXDzZidbTqNwzl8RsFLJp6U-kD8Pd14L1zVrK5V5rGno | G80: 894000000000000 | H80: 894000000000000 | I80: Media Access Expired | J80: 已重新下載
A81: 198 | B81: 2025-09-24 11:29:26+00:00 | C81: 2025-09-24 12:00:48+00:00 | D81: 🎩Davio🎩 | E81: davio_magic | F81: https://lookaside.facebook.com/mcl/multimedia/lookaside/?download_info=AZuiVSa2PwBr-jvueTw31bq4IRU8QES3kPr0Foi_yDXIpUIEKuqs4DBe5Bn55uTU4zpUhQIknGTua5Jr_tYcR4wRgF-l_chlS11Vw1_6vA_TRUpApI-lsSF7xGeAxj6McWwqS7YGJWz-s3sneLGWmh4WQJsw | G81: 2.79e+15 | H81: 2.79e+15 | I81: Media Access Expired | J81: 已重新下載
A82: 7 | B82: 2025-06-06 11:43:40+00:00 | C82: 2025-12-17 15:23:29+00:00 | D82: 蛋哥超有事EggThings | E82: egg_things | F82: https://lookaside.facebook.com/mcl/multimedia/lookaside/?download_info=AZufqzvXa07Se0fpUw1kxUJCeKN9tB-TQcnLObFUBGZo72YncOP-_s1yIcVECmgtTuI7eCYVs_iV52OezUTwGIJ491gHWYy1fCcOCGCLKP_8AKVkKNEqv1UfznAucEMCKJH_J4n5kjZNUJp9BnBVxIn8_-9I | G82: 1.44e+15 | H82: 1.44e+15 | I82: g
A83: 26 | B83: 2025-03-23 07:21:45+00:00 | C83: 2025-03-25 16:21:51+00:00 | D83: 小象愛出門 | E83: elephant_gogo | F83: https://lookaside.facebook.com/mcl/multimedia/lookaside/?download_info=AZvje7-AF2jYaOM3Ib11edSrThWluhCMeFlZlmLl4pzvpDBJApL5uNp-qyPqj7_nwLfx9QHcC7PTrvys11E6UmB57EG8i_8kmgel8yU3BegZpxnQeJ_5IK4ICdYCvppCt3kwBSWNF3Oif9LpfFXlxfvSYT-0 | G83: 1.26e+15 | H83: 1.26e+15 | I83: c
A84: 27 | B84: 2025-03-23 09:57:28+00:00 | C84: 2025-03-25 12:57:34+00:00 | D84: 小象愛出門 | E84: elephant_gogo | F84: https://lookaside.facebook.com/mcl/multimedia/lookaside/?download_info=AZv1CnZEyjIAnUGkMkm-lkoeAxrR3Ft8wpwp9t2hwjbZT7fSXr1D1bL-Go3O1CfH4KO5O2q_ODTTln7QO973km5MtnMi1HuPZpStBuUa2QDKA70mXEUvfIPlbMnq4aOOt1k1CJF8Hab0WtHqnl2CpQdkyVKH | G84: 1.26e+15 | H84: 1.26e+15 | I84: c
A85: 29 | B85: 2025-03-25 17:55:41+00:00 | C85: 2025-03-27 19:55:46+00:00 | D85: 小象愛出門 | E85: elephant_gogo | F85: https://lookaside.facebook.com/mcl/multimedia/lookaside/?download_info=AZsvLe8ATWe7_JNIs0PBGIRA4JBGK3m26P8qUJA_meICos6IY8GVPSBRfMp44MPpJvA7GjRWi_3TbWtDphwv8gv_KJSSMeauYhp6pm9Ask_vdRjGSyV08qvm7G74jmibxcGyLQUnFXZC1MiUcfEekI-dtURM | G85: 2.1e+15 | H85: 2.1e+15 | I85: c
A86: 30 | B86: 2025-03-26 01:11:55+00:00 | C86: 2026-01-14 22:44:45+00:00 | D86: 小象愛出門 | E86: elephant_gogo | F86: https://lookaside.facebook.com/mcl/multimedia/lookaside/?download_info=AZtl98pi4kfOaAhd0S2w-f6nSbVkUVEEPTKt_uX3PAUL7XLSHlASdB6omFFQ3KZLlX8M84g9APINVyE1cV_5yWEMQsFEE4L5FDrED31ZhLELH68tfkydQyBBszigWvYQcdsTgDb4klBeR2dHm-mnxzUOcBI | G86: 884000000000000 | H86: 884000000000000 | I86: c
A87: 77 | B87: 2025-09-04 09:14:09+00:00 | C87: 2025-09-05 10:54:14+00:00 | D87: 小象愛出門 | E87: elephant_gogo | F87: https://lookaside.facebook.com/mcl/multimedia/lookaside/?download_info=AZuLYGbuwwJCghz_oOgjfNNS_GN7zL1Gkp-4Xj5W5X3sQyPH9tt6RmtppwQkXK4IsQv_JwB6cgsyAfp-fFrcPeWVeDXVWy_gDind2kI2uf8Gkar8akKQmHfDo8DzyO6O_KWBthPYmOflW1ByvNay7NSpTZU | G87: 835000000000000 | H87: 835000000000000 | I87: c
A88: 94 | B88: 2025-11-11 07:14:10+00:00 | C88: 2025-11-14 08:04:15+00:00 | D88: 小象愛出門 | E88: elephant_gogo | F88: https://lookaside.facebook.com/mcl/multimedia/lookaside/?download_info=AZtchUKsfldBDm7z8Iqs_zlVU3AbDYnaz__IE36AgbdheUrenixOXf0MC7vzj2qhASIMMz8YhsHHUl9uKvhJWFgDucpRvqTAWyjQHAYxCMRGvt9L0iL1Z61T6WfRv6og42zhtPF0onefLzu4EBEVdABeJy92 | G88: 1.47e+15 | H88: 1.47e+15 | I88: c
A89: 7 | B89: 2025-02-26 13:37:30+00:00 | C89: 2025-04-29 19:59:17+00:00 | D89: 健人蓋伊 | E89: gu_yuze | F89: https://lookaside.facebook.com/mcl/multimedia/lookaside/?download_info=AZuuXfQadBZmecEnY8NOjQ9z7M0mgRhW8x9Q7SplhC-epolGB0Ncxc26Wj4gvgczTWvMfiMGAFRjZaopv3aFSR1y2Z817cAPazyQBnfSg_vPNTOu7E8t7JxDL7R45o3jlfTbL1eBmohF8j63gtHmc3CXUnE | G89: 733000000000000 | H89: 733000000000000 | I89: c
...

Sheet 「aisa200」的副本
A1: Aisa_Order | B1: person_name | C1: ig_name | D1: ig_id | E1: ig_strong_id | F1: done | G1: posts | H1: Followers | I1: Following | J1: ig_url | K1: ig_url ig_private | L1: ig_notSure_notFound | M1: ig_repeat | N1: category | O1: followers
A2: 1 | B2: 蔡阿嘎 | C2: 蔡阿嘎 | D2: yga0721 | E2: 45717781 | F2: 1 | J2: https://www.instagram.com/yga0721/ | N2: 趣味搞笑 | O2: 5893570
A3: 2 | B3: Joeman | C3: Joeman 九妹 | D3: joemanweng | E3: 360484090 | F3: g | J3: https://www.instagram.com/joemanweng/ | N3: 美食料理,3C科技,趣味搞笑 | O3: 3987069
A4: 3 | B4: 黃阿瑪的後宮生活 | C4: 黃阿瑪的後宮生活 | D4: fumeancat | E4: 1399123752 | F4: 1 | G4: 4527 | H4: 105萬 | I4: 159 | J4: https://www.instagram.com/fumeancat/ | N4: 寵物 | O4: 4118794
A5: 4 | B5: 千千進食中 | C5: 千千 | D5: khshu_ | E5: 254432523 | F5: g | G5: 989 | H5: 88.8萬 | I5: 962 | J5: https://www.instagram.com/khshu_/ | N5: 美食料理 | O5: 3609387
A6: 5 | B6: 小象愛出門 | C6: 小象愛出門 | D6: elephant_gogo | E6: 484667815 | F6: g | J6: https://www.instagram.com/elephant_gogo/ | N6: 美食料理,旅遊 | O6: 1160238
A7: 6 | B7: 那對夫妻 | C7: 那對夫妻Nico&Kim | D7: 1006nk | E7: 1701651749 | F7: 1 | J7: https://www.instagram.com/1006nk/ | N7: 趣味搞笑,家庭母嬰,表演藝術 | O7: 4578282
A8: 7 | B8: How-Fun-如何爽 | C8: HowHow | D8: howhowhasfriends | E8: 6505088311 | F8: 1 | J8: https://www.instagram.com/howhowhasfriends | N8: 趣味搞笑 | O8: 2758663
A9: 8 | B9: PanSci 泛科學 | C9: PanSci 泛科學 | D9: pansci | E9: 1455058965 | F9: 1 | J9: https://www.instagram.com/pansci/ | N9: 知識教育 | O9: 1900400
A10: 9 | B10: 一隻阿圓 | C10: 一隻阿圓 | D10: nanaciaociao | E10: 313471712 | F10: 1 | G10: 3490 | H10: 56.1萬 | I10: 1038 | J10: https://www.instagram.com/nanaciaociao/ | N10: 美妝保養,時尚潮流,旅遊 | O10: 1734796
A11: 10 | B11: 欸你這週要幹嘛 | C11: 欸你這週要幹嘛 | D11: arielsvlog_816 | E11: 8320554996 | F11: 1 | J11: https://www.instagram.com/arielsvlog_816/ | N11: 趣味搞笑 | O11: 2339911
A12: 11 | B12: 77老大 | C12: 77老大 | D12: basil_77777 | E12: 1 | F12: https://www.instagram.com/basil_77777/ | N12: 醫療健康,知識教育 | O12: 2808129
A13: 12 | B13: 那個女生 Kiki | N13: 美食料理,知識教育 | O13: 1793484
A14: 13 | B14: 阿滴英文 | N14: 知識教育 | O14: 4987120
A15: 14 | B15: 好味小姐 | C15: 好味小姐與蛋捲,短褲,麻糊,米香,橘皮,本丸,圓仔,More | D15: ladyflavor | E15: 3417748590 | F15: 1 | J15: https://www.instagram.com/ladyflavor/ | N15: 美食料理,寵物 | O15: 1592539
A16: 14 | B16: 好味小姐 | C16: 好味小姐脆脆 | D16: ladyflavor_cui | E16: 3656815405 | F16: 1 | J16: https://www.instagram.com/ladyflavor_cui/
A17: 14 | B17: 好味小姐 | C17: 好味小姐腦波弱跟Podcast | D17: ladyflavor_nowpo | E17: 53675526308 | F17: 1 | J17: https://www.instagram.com/ladyflavor_nowpo/
A18: 15 | B18: 廉傑克曼 | C18: 張廉傑 RJ / 阿傑 | D18: jaychang0127 | E18: 328078093 | F18: g | G18: 1841 | H18: 41.3萬 | I18: 4009 | J18: https://www.instagram.com/jaychang0127/ | N18: 遊戲電玩 | O18: 1170390
A19: 16 | B19: 江老師 | C19: 我是江老師 | D19: teacherchiang | E19: 30136496472 | F19: g | G19: 1898 | H19: 30.6萬 | I19: 621 | J19: https://www.instagram.com/teacherchiang | N19: 表演藝術,時尚潮流,家庭母嬰 | O19: 1343583
A20: 17 | B20: 那些電影教我的事 | C20: 那些電影教我的事 | D20: lessonsfrommovies | E20: 485234984 | F20: 1 | J20: https://www.instagram.com/lessonsfrommovies/ | N20: 影視評論 | O20: 3862684
A21: 18 | B21: 豆漿--Soybean-Milk | C21: 豆漿-SoybeanMilk | D21: soybeanmilk_cat | E21: 5556187464 | F21: 1 | J21: https://www.instagram.com/soybeanmilk_cat/ | N21: 寵物 | O21: 1835218
A22: 19 | B22: Onion-man-洋蔥先生與阿文 | C22: 洋蔥先生與阿文 | D22: onionman__ | E22: 1981431196 | F22: g | G22: 1172 | H22: 45.7萬 | I22: 921 | J22: https://www.instagram.com/onionman__/ | N22: 表演藝術,趣味搞笑 | O22: 3133655
A23: 20 | B23: 人類超有病 Baxuan | C23: 霸軒BAXUAN | D23: baxuan_ig | E23: 1959578996 | F23: g | G23: 1061 | H23: 73.9萬 | I23: 2826 | J23: https://www.instagram.com/baxuan_ig/ | N23: 表演藝術,趣味搞笑 | O23: 2789691
A24: 21 | B24: 大蛇丸 | C24: 大蛇丸 | D24: jam_cutepig | E24: 2214964723 | F24: 1 | J24: https://www.instagram.com/jam_cutepig/ | N24: 趣味搞笑 | O24: 2040947
A25: 22 | B25: Andy老師 | C25: Andy老師 | D25: andy1994x | E25: 4017891221 | F25: 1 | J25: https://www.instagram.com/andy1994x/ | N25: 趣味搞笑,表演藝術 | O25: 4471750
A26: 23 | B26: 超認真少年-I'm-Serious | C26: 超認真少年 | D26: imseriou | E26: 8743462644 | F26: g | G26: 1517 | H26: 13.7萬 | I26: 744 | J26: https://www.instagram.com/imseriou/ | N26: 知識教育 | O26: 1219271
A27: 24 | B27: 三原慧悟-Sanyuan_JAPAN | C27: 三原 慧悟/サンエン/Mr.3 | D27: sanyuan_japan | E27: 2036845994 | F27: 1 | J27: https://www.instagram.com/sanyuan_japan/ | N27: 旅遊,趣味搞笑 | O27: 2199000
A28: 25 | B28: 貓貓蟲-咖波 | C28: Bugcat Capoo | D28: bugcat_capoo | E28: 2122019014 | F28: 1 | J28: https://www.instagram.com/bugcat_capoo/ | N28: 表演藝術 | O28: 6539880
A29: 26 | B29: Ian&Eric | N29: 旅遊,趣味搞笑 | O29: 2226005
A30: 27 | B30: 黃氏兄弟 | C30: 黃氏兄弟 | D30: huangbrotherss | E30: 6231869789 | F30: 1 | J30: https://www.instagram.com/huangbrotherss/ | N30: 趣味搞笑,表演藝術 | O30: 3051036
A31: 28 | B31: 我得了一種吃菜就會死的病-微疼 | N31: 表演藝術,趣味搞笑 | O31: 2509942
A32: 29 | B32: 琳妲-林羿禎 | C32: 琳妲-林羿禎💕 | D32: linda831212 | E32: 262292089 | F32: g | G32: 5210 | H32: 98.7萬 | I32: 2400 | J32: https://www.instagram.com/linda831212/ | N32: 表演藝術,趣味搞笑 | O32: 2688159
A33: 30 | B33: 白癡公主 | C33: 白癡公主 | D33: 87acup | E33: 323227199 | F33: 1 | J33: https://www.instagram.com/87acup/ | N33: 趣味搞笑 | O33: 3796221
A34: 31 | B34: KEOKI BLACK布萊克薛薛 | C34: 布萊克薛薛Drangadrang | D34: k3okii | E34: 192726292 | F34: 1 | J34: https://www.instagram.com/k3okii/ | N34: 旅遊,美食料理 | O34: 1200469
A35: 32 | B35: 厭世甜點店 | N35: 美食料理 | O35: 817219
A36: 33 | B36: 陳彥婷 | C36: 陳彥婷 Tiffany | D36: thetiffanychen | E36: 4053642540 | F36: 1 | J36: https://www.instagram.com/thetiffanychen/ | N36: 趣味搞笑 | O36: 1601595
A37: 34 | B37: 魚乾 | C37: 魚乾 | D37: annie72127 | E37: 310596431 | F37: 1 | J37: https://www.instagram.com/annie72127/ | N37: 寵物,遊戲電玩,趣味搞笑 | O37: 2023760
A38: 35 | B38: 志祺七七 | C38: 志祺 | D38: shasha77.daily | E38: 7011513421 | F38: 1 | J38: https://www.instagram.com/shasha77.daily/ | N38: 知識教育,時事討論,高階經理人 | O38: 1935680
A39: 36 | B39: HOOK | C39: HOOK | D39: helloiamhook | E39: 6666970922 | F39: 1 | J39: https://www.instagram.com/helloiamhook/ | N39: 寵物,旅遊,美食料理 | O39: 2877515
A40: 37 | B40: 木曜4超玩 | C40: 木曜4超玩 | D40: muyao4 | E40: 5422332449 | F40: 1 | J40: https://www.instagram.com/muyao4/ | N40: 旅遊 | O40: 3229080
...

Sheet AisaKolTop200新增
A1: Aisa_Order | B1: person_name | C1: Top200新增 | D1: ig_name | E1: ig_id | F1: ig_strong_id | G1: done | H1: posts | I1: Followers | J1: Following | K1: ig_url | L1: ig_url ig_private | M1: ig_notSure_notFound | N1: ig_repeat | O1: category | P1: followers
A2: 1 | B2: 蔡阿嘎 | C2: =IF(LEN(D2)>0,,1) -> 0 | D2: 蔡阿嘎 | E2: yga0721 | F2: 45717781 | G2: 1 | K2: https://www.instagram.com/yga0721/ | O2: 趣味搞笑 | P2: 5893570
A3: 2 | B3: Joeman | C3: =IF(LEN(D3)>0,,1) -> 0 | D3: Joeman 九妹 | E3: joemanweng | F3: 360484090 | G3: g | K3: https://www.instagram.com/joemanweng/ | O3: 美食料理,3C科技,趣味搞笑 | P3: 3987069
A4: 3 | B4: 黃阿瑪的後宮生活 | C4: =IF(LEN(D4)>0,,1) -> 0 | D4: 黃阿瑪的後宮生活 | E4: fumeancat | F4: 1399123752 | G4: 1 | H4: 4527 | I4: 105萬 | J4: 159 | K4: https://www.instagram.com/fumeancat/ | O4: 寵物 | P4: 4118794
A5: 4 | B5: 千千進食中 | C5: =IF(LEN(D5)>0,,1) -> 0 | D5: 千千 | E5: khshu_ | F5: 254432523 | G5: g | H5: 989 | I5: 88.8萬 | J5: 962 | K5: https://www.instagram.com/khshu_/ | O5: 美食料理 | P5: 3609387
A6: 5 | B6: 小象愛出門 | C6: =IF(LEN(D6)>0,,1) -> 0 | D6: 小象愛出門 | E6: elephant_gogo | F6: 484667815 | G6: g | K6: https://www.instagram.com/elephant_gogo/ | O6: 美食料理,旅遊 | P6: 1160238
A7: 6 | B7: 那對夫妻 | C7: =IF(LEN(D7)>0,,1) -> 0 | D7: 那對夫妻Nico&Kim | E7: 1006nk | F7: 1701651749 | G7: 1 | K7: https://www.instagram.com/1006nk/ | O7: 趣味搞笑,家庭母嬰,表演藝術 | P7: 4578282
A8: 7 | B8: How-Fun-如何爽 | C8: =IF(LEN(D8)>0,,1) -> 0 | D8: HowHow | E8: howhowhasfriends | F8: 6505088311 | G8: 1 | K8: https://www.instagram.com/howhowhasfriends | O8: 趣味搞笑 | P8: 2758663
A9: 8 | B9: PanSci 泛科學 | C9: =IF(LEN(D9)>0,,1) -> 0 | D9: PanSci 泛科學 | E9: pansci | F9: 1455058965 | G9: 1 | K9: https://www.instagram.com/pansci/ | O9: 知識教育 | P9: 1900400
A10: 9 | B10: 一隻阿圓 | C10: =IF(LEN(D10)>0,,1) -> 0 | D10: 一隻阿圓 | E10: nanaciaociao | F10: 313471712 | G10: 1 | H10: 3490 | I10: 56.1萬 | J10: 1038 | K10: https://www.instagram.com/nanaciaociao/ | O10: 美妝保養,時尚潮流,旅遊 | P10: 1734796
A11: 10 | B11: 欸你這週要幹嘛 | C11: =IF(LEN(D11)>0,,1) -> 0 | D11: 欸你這週要幹嘛 | E11: arielsvlog_816 | F11: 8320554996 | G11: 1 | K11: https://www.instagram.com/arielsvlog_816/ | O11: 趣味搞笑 | P11: 2339911
A12: 11 | B12: 77老大 | C12: =IF(LEN(D12)>0,,1) -> 0 | D12: 77老大 | E12: basil_77777 | F12: 1 | G12: https://www.instagram.com/basil_77777/ | O12: 醫療健康,知識教育 | P12: 2808129
A13: 12 | B13: 那個女生 Kiki | C13: =IF(LEN(D13)>0,,1) -> 1 | O13: 美食料理,知識教育 | P13: 1793484
A14: 13 | B14: 阿滴英文 | C14: =IF(LEN(D14)>0,,1) -> 1 | O14: 知識教育 | P14: 4987120
A15: 14 | B15: 好味小姐 | C15: =IF(LEN(D15)>0,,1) -> 0 | D15: 好味小姐與蛋捲,短褲,麻糊,米香,橘皮,本丸,圓仔,More | E15: ladyflavor | F15: 3417748590 | G15: 1 | K15: https://www.instagram.com/ladyflavor/ | O15: 美食料理,寵物 | P15: 1592539
A16: 14 | B16: 好味小姐 | C16: =IF(LEN(D16)>0,,1) -> 0 | D16: 好味小姐脆脆 | E16: ladyflavor_cui | F16: 3656815405 | G16: 1 | K16: https://www.instagram.com/ladyflavor_cui/
A17: 14 | B17: 好味小姐 | C17: =IF(LEN(D17)>0,,1) -> 0 | D17: 好味小姐腦波弱跟Podcast | E17: ladyflavor_nowpo | F17: 53675526308 | G17: 1 | K17: https://www.instagram.com/ladyflavor_nowpo/
A18: 15 | B18: 廉傑克曼 | C18: =IF(LEN(D18)>0,,1) -> 0 | D18: 張廉傑 RJ / 阿傑 | E18: jaychang0127 | F18: 328078093 | G18: g | H18: 1841 | I18: 41.3萬 | J18: 4009 | K18: https://www.instagram.com/jaychang0127/ | O18: 遊戲電玩 | P18: 1170390
A19: 16 | B19: 江老師 | C19: =IF(LEN(D19)>0,,1) -> 0 | D19: 我是江老師 | E19: teacherchiang | F19: 30136496472 | G19: g | H19: 1898 | I19: 30.6萬 | J19: 621 | K19: https://www.instagram.com/teacherchiang | O19: 表演藝術,時尚潮流,家庭母嬰 | P19: 1343583
A20: 17 | B20: 那些電影教我的事 | C20: =IF(LEN(D20)>0,,1) -> 0 | D20: 那些電影教我的事 | E20: lessonsfrommovies | F20: 485234984 | G20: 1 | K20: https://www.instagram.com/lessonsfrommovies/ | O20: 影視評論 | P20: 3862684
A21: 18 | B21: 豆漿--Soybean-Milk | C21: =IF(LEN(D21)>0,,1) -> 0 | D21: 豆漿-SoybeanMilk | E21: soybeanmilk_cat | F21: 5556187464 | G21: 1 | K21: https://www.instagram.com/soybeanmilk_cat/ | O21: 寵物 | P21: 1835218
A22: 19 | B22: Onion-man-洋蔥先生與阿文 | C22: =IF(LEN(D22)>0,,1) -> 0 | D22: 洋蔥先生與阿文 | E22: onionman__ | F22: 1981431196 | G22: g | H22: 1172 | I22: 45.7萬 | J22: 921 | K22: https://www.instagram.com/onionman__/ | O22: 表演藝術,趣味搞笑 | P22: 3133655
A23: 20 | B23: 人類超有病 Baxuan | C23: =IF(LEN(D23)>0,,1) -> 0 | D23: 霸軒BAXUAN | E23: baxuan_ig | F23: 1959578996 | G23: g | H23: 1061 | I23: 73.9萬 | J23: 2826 | K23: https://www.instagram.com/baxuan_ig/ | O23: 表演藝術,趣味搞笑 | P23: 2789691
A24: 21 | B24: 大蛇丸 | C24: =IF(LEN(D24)>0,,1) -> 0 | D24: 大蛇丸 | E24: jam_cutepig | F24: 2214964723 | G24: 1 | K24: https://www.instagram.com/jam_cutepig/ | O24: 趣味搞笑 | P24: 2040947
A25: 22 | B25: Andy老師 | C25: =IF(LEN(D25)>0,,1) -> 0 | D25: Andy老師 | E25: andy1994x | F25: 4017891221 | G25: 1 | K25: https://www.instagram.com/andy1994x/ | O25: 趣味搞笑,表演藝術 | P25: 4471750
A26: 23 | B26: 超認真少年-I'm-Serious | C26: =IF(LEN(D26)>0,,1) -> 0 | D26: 超認真少年 | E26: imseriou | F26: 8743462644 | G26: g | H26: 1517 | I26: 13.7萬 | J26: 744 | K26: https://www.instagram.com/imseriou/ | O26: 知識教育 | P26: 1219271
A27: 24 | B27: 三原慧悟-Sanyuan_JAPAN | C27: =IF(LEN(D27)>0,,1) -> 0 | D27: 三原 慧悟/サンエン/Mr.3 | E27: sanyuan_japan | F27: 2036845994 | G27: 1 | K27: https://www.instagram.com/sanyuan_japan/ | O27: 旅遊,趣味搞笑 | P27: 2199000
A28: 25 | B28: 貓貓蟲-咖波 | C28: =IF(LEN(D28)>0,,1) -> 0 | D28: Bugcat Capoo | E28: bugcat_capoo | F28: 2122019014 | G28: 1 | K28: https://www.instagram.com/bugcat_capoo/ | O28: 表演藝術 | P28: 6539880
A29: 26 | B29: Ian&Eric | C29: =IF(LEN(D29)>0,,1) -> 1 | O29: 旅遊,趣味搞笑 | P29: 2226005
A30: 27 | B30: 黃氏兄弟 | C30: =IF(LEN(D30)>0,,1) -> 0 | D30: 黃氏兄弟 | E30: huangbrotherss | F30: 6231869789 | G30: 1 | K30: https://www.instagram.com/huangbrotherss/ | O30: 趣味搞笑,表演藝術 | P30: 3051036
A31: 28 | B31: 我得了一種吃菜就會死的病-微疼 | C31: =IF(LEN(D31)>0,,1) -> 1 | O31: 表演藝術,趣味搞笑 | P31: 2509942
A32: 29 | B32: 琳妲-林羿禎 | C32: =IF(LEN(D32)>0,,1) -> 0 | D32: 琳妲-林羿禎💕 | E32: linda831212 | F32: 262292089 | G32: g | H32: 5210 | I32: 98.7萬 | J32: 2400 | K32: https://www.instagram.com/linda831212/ | O32: 表演藝術,趣味搞笑 | P32: 2688159
A33: 30 | B33: 白癡公主 | C33: =IF(LEN(D33)>0,,1) -> 0 | D33: 白癡公主 | E33: 87acup | F33: 323227199 | G33: 1 | K33: https://www.instagram.com/87acup/ | O33: 趣味搞笑 | P33: 3796221
A34: 31 | B34: KEOKI BLACK布萊克薛薛 | C34: =IF(LEN(D34)>0,,1) -> 0 | D34: 布萊克薛薛Drangadrang | E34: k3okii | F34: 192726292 | G34: 1 | K34: https://www.instagram.com/k3okii/ | O34: 旅遊,美食料理 | P34: 1200469
A35: 32 | B35: 厭世甜點店 | C35: =IF(LEN(D35)>0,,1) -> 1 | O35: 美食料理 | P35: 817219
A36: 33 | B36: 陳彥婷 | C36: =IF(LEN(D36)>0,,1) -> 0 | D36: 陳彥婷 Tiffany | E36: thetiffanychen | F36: 4053642540 | G36: 1 | K36: https://www.instagram.com/thetiffanychen/ | O36: 趣味搞笑 | P36: 1601595
A37: 34 | B37: 魚乾 | C37: =IF(LEN(D37)>0,,1) -> 0 | D37: 魚乾 | E37: annie72127 | F37: 310596431 | G37: 1 | K37: https://www.instagram.com/annie72127/ | O37: 寵物,遊戲電玩,趣味搞笑 | P37: 2023760
A38: 35 | B38: 志祺七七 | C38: =IF(LEN(D38)>0,,1) -> 0 | D38: 志祺 | E38: shasha77.daily | F38: 7011513421 | G38: 1 | K38: https://www.instagram.com/shasha77.daily/ | O38: 知識教育,時事討論,高階經理人 | P38: 1935680
A39: 36 | B39: HOOK | C39: =IF(LEN(D39)>0,,1) -> 0 | D39: HOOK | E39: helloiamhook | F39: 6666970922 | G39: 1 | K39: https://www.instagram.com/helloiamhook/ | O39: 寵物,旅遊,美食料理 | P39: 2877515
A40: 37 | B40: 木曜4超玩 | C40: =IF(LEN(D40)>0,,1) -> 0 | D40: 木曜4超玩 | E40: muyao4 | F40: 5422332449 | G40: 1 | K40: https://www.instagram.com/muyao4/ | O40: 旅遊 | P40: 3229080
...

Sheet Merged
A1: Aisa_Order | B1: Temperature_order | C1: both | D1: person_name | E1: ig_name | F1: ig_id | G1: ig_strong_id | H1: done | I1: posts | J1: Followers | K1: Following | L1: ig_url | M1: ig_private | N1: ig_notSure_notFound | O1: ig_repeat | P1: temperature_link
A2: 1 | B2: 2 | C2: Y | D2: 蔡阿嘎 蔡緯嘉 | E2: 蔡阿嘎 | F2: yga0721 | G2: 45717781 | H2: 1 | L2: https://www.instagram.com/yga0721/ | P2: https://dailyview.tw/top100/item/1246?theme=36&range=30
A3: 2 | D3: PanSci 泛科學 | E3: PanSci 泛科學 | F3: pansci | G3: 1455058965 | H3: 1 | L3: https://www.instagram.com/pansci/
A4: 3 | D4: 黃阿瑪的後宮生活 | E4: 黃阿瑪的後宮生活 | F4: fumeancat | G4: 1399123752 | H4: 1 | I4: 4527 | J4: 105萬 | K4: 159 | L4: https://www.instagram.com/fumeancat/
A5: 4 | D5: 小象愛出門 | E5: 小象愛出門 | F5: elephant_gogo | G5: 484667815 | H5: g | L5: https://www.instagram.com/elephant_gogo/
A6: 5 | B6: 123 | C6: Y | D6: 品筠&京燁（那對夫妻） | E6: 那對夫妻Nico&Kim | F6: 1006nk | G6: 1701651749 | H6: 1 | L6: https://www.instagram.com/1006nk/ | P6: https://dailyview.tw/top100/item/1259?theme=36&range=30
A7: 6 | B7: 62 | C7: Y | D7: 蛇丸 | E7: 大蛇丸 | F7: jam_cutepig | G7: 2214964723 | H7: 1 | L7: https://www.instagram.com/jam_cutepig/ | P7: https://dailyview.tw/top100/item/13874?theme=36&range=30
A8: 7 | B8: 161 | C8: Y | D8: 艾瑞絲 Aries | E8: Aries艾瑞絲 | F8: aries_8248 | G8: 453456033 | H8: g | I8: 2021 | J8: 77.4萬 | K8: 938 | L8: https://www.instagram.com/aries_8248/ | P8: https://dailyview.tw/top100/item/2778?theme=36&range=30
A9: 8 | D9: 陳彥婷 | E9: 陳彥婷 Tiffany | F9: thetiffanychen | G9: 4053642540 | H9: 1 | L9: https://www.instagram.com/thetiffanychen/
A10: 9 | D10: Joeman | E10: Joeman 九妹 | F10: joemanweng | G10: 360484090 | H10: g | L10: https://www.instagram.com/joemanweng/
A11: 10 | B11: 77 | C11: Y | D11: 一隻阿圓 | E11: 一隻阿圓 | F11: nanaciaociao | G11: 313471712 | H11: 1 | I11: 3490 | J11: 56.1萬 | K11: 1038 | L11: https://www.instagram.com/nanaciaociao/ | P11: https://dailyview.tw/top100/item/13075?theme=36&range=30
A12: 11 | D12: 豆漿- Soybean Milk | E12: 豆漿-SoybeanMilk | F12: soybeanmilk_cat | G12: 5556187464 | H12: 1 | L12: https://www.instagram.com/soybeanmilk_cat/
A13: 12 | B13: 7 | C13: Y | D13: 亞拉（貓貓蟲咖波） | E13: Bugcat Capoo | F13: bugcat_capoo | G13: 2122019014 | H13: 1 | L13: https://www.instagram.com/bugcat_capoo/ | P13: https://dailyview.tw/top100/item/3047?theme=36&range=30
A14: 13 | B14: 56 | C14: Y | D14: 霸軒與小美 Baxuan & Mei | E14: 霸軒BAXUAN | F14: baxuan_ig | G14: 1959578996 | H14: g | I14: 1061 | J14: 73.9萬 | K14: 2826 | L14: https://www.instagram.com/baxuan_ig/ | P14: https://dailyview.tw/top100/item/23575?theme=36&range=30
A15: 14 | D15: 蕾菈 Lyla | E15: 蕾菈 Lyla | F15: la.112814 | G15: 534488377 | H15: g | L15: https://www.instagram.com/la.112814/
A16: 15 | B16: 54 | C16: Y | D16: 好味小姐 Lady Flavor | E16: 好味小姐與蛋捲,短褲,麻糊,米香,橘皮,本丸,圓仔,More | F16: ladyflavor | G16: 3417748590 | H16: 1 | L16: https://www.instagram.com/ladyflavor/ | P16: https://dailyview.tw/top100/item/12056?theme=36&range=30
A17: 15 | B17: 54 | C17: Y | D17: 好味小姐 Lady Flavor | E17: 好味小姐脆脆 | F17: ladyflavor_cui | G17: 3656815405 | H17: 1 | L17: https://www.instagram.com/ladyflavor_cui/ | P17: https://dailyview.tw/top100/item/12056?theme=36&range=30
A18: 15 | B18: 54 | C18: Y | D18: 好味小姐 Lady Flavor | E18: 好味小姐腦波弱跟Podcast | F18: ladyflavor_nowpo | G18: 53675526308 | H18: 1 | L18: https://www.instagram.com/ladyflavor_nowpo/ | P18: https://dailyview.tw/top100/item/12056?theme=36&range=30
A19: 16 | D19: 小A辣 | E19: 小A辣🌶️ | F19: ala780705 | G19: 5703523434 | H19: g | I19: 1756 | J19: 35.3萬 | K19: 1481 | L19: https://www.instagram.com/ala780705/
A20: 17 | B20: 199 | C20: Y | D20: 泱泱 吳泱潾 LYNN | E20: 泱泱LYNN | F20: lynnwu0219_2 | G20: 47642521277 | H20: 1 | L20: https://www.instagram.com/lynnwu0219_2/ | P20: https://dailyview.tw/top100/item/9605?theme=36&range=30
A21: 18 | B21: 63 | C21: Y | D21: 千千 Chien-Chien | E21: 千千 | F21: khshu_ | G21: 254432523 | H21: g | I21: 989 | J21: 88.8萬 | K21: 962 | L21: https://www.instagram.com/khshu_/ | P21: https://dailyview.tw/top100/item/3673?theme=36&range=30
